<mujoco model="double_pendulum">
    <option timestep="0.01" integrator="RK4">
        <flag warmstart="enable" energy="enable" contact="enable" />
    </option>

    <asset>
        <material name="red" rgba="0.8 0.2 0.2 1" />
        <material name="blue" rgba="0.2 0.2 0.8 1" />
        <material name="green" rgba="0.2 0.8 0.2 1" />
        <material name="purple" rgba="0.5 0.2 0.8 1" />
        <material name="floor" rgba="0.9 0.9 0.9 1" specular="0.1" />
    </asset>

    <worldbody>
        <!-- Floor -->
        <geom name="floor" type="plane" size="10 10 0.1" material="floor" />

        <!-- Light source -->
        <light directional="true" pos="0 0 5" dir="0 0 -1" />
        <light directional="true" pos="0 5 2" dir="0 -1 -0.5" />

        <!-- Fixed base for pendulum -->
        <body name="base" pos="0 0 2">
            <geom name="base_geom" type="sphere" size="0.06" material="red" />

            <!-- First pendulum segment -->
            <body name="upper_arm" pos="0 0 0">
                <joint name="shoulder" type="hinge" axis="0 1 0" damping="0.05" />
                <geom name="upper_arm_geom" type="capsule" fromto="0 0 0 0 0 -0.7" size="0.03" material="blue" />

                <!-- Second pendulum segment -->
                <body name="lower_arm" pos="0 0 -0.7">
                    <joint name="elbow" type="hinge" axis="0 1 0" damping="0.05" />
                    <geom name="lower_arm_geom" type="capsule" fromto="0 0 0 0 0 -0.6" size="0.025" material="green" />
                    <geom name="end_mass" type="sphere" pos="0 0 -0.6" size="0.08" material="purple" />
                </body>
            </body>
        </body>
    </worldbody>

    <keyframe>
        <!-- Start configuration with both arms at slight angles -->
        <key name="start" qpos="0.3 0.7" />
    </keyframe>
</mujoco>
